Internal Server Error: /swagger/
Traceback (most recent call last):
  File "/usr/local/lib/python3.8/site-packages/django/core/handlers/exception.py", line 47, in inner
    response = get_response(request)
  File "/usr/local/lib/python3.8/site-packages/django/core/handlers/base.py", line 181, in _get_response
    response = wrapped_callback(request, *callback_args, **callback_kwargs)
  File "/usr/local/lib/python3.8/site-packages/django/views/decorators/csrf.py", line 54, in wrapped_view
    return view_func(*args, **kwargs)
  File "/usr/local/lib/python3.8/site-packages/django/views/generic/base.py", line 70, in view
    return self.dispatch(request, *args, **kwargs)
  File "/usr/local/lib/python3.8/site-packages/rest_framework/views.py", line 509, in dispatch
    response = self.handle_exception(exc)
  File "/usr/local/lib/python3.8/site-packages/rest_framework/views.py", line 469, in handle_exception
    self.raise_uncaught_exception(exc)
  File "/usr/local/lib/python3.8/site-packages/rest_framework/views.py", line 480, in raise_uncaught_exception
    raise exc
  File "/usr/local/lib/python3.8/site-packages/rest_framework/views.py", line 506, in dispatch
    response = handler(request, *args, **kwargs)
  File "/usr/local/lib/python3.8/site-packages/rest_framework_swagger/views.py", line 32, in get
    schema = generator.get_schema(request=request)
  File "/usr/local/lib/python3.8/site-packages/rest_framework/schemas/coreapi.py", line 156, in get_schema
    links = self.get_links(None if public else request)
  File "/usr/local/lib/python3.8/site-packages/rest_framework/schemas/coreapi.py", line 143, in get_links
    link = view.schema.get_link(path, method, base_url=self.url)
AttributeError: 'AutoSchema' object has no attribute 'get_link'
Not Found: /favicon.ico
Internal Server Error: /swagger/
Traceback (most recent call last):
  File "/usr/local/lib/python3.8/site-packages/django/template/defaulttags.py", line 1034, in find_library
    return parser.libraries[name]
KeyError: 'staticfiles'

During handling of the above exception, another exception occurred:

Traceback (most recent call last):
  File "/usr/local/lib/python3.8/site-packages/django/core/handlers/exception.py", line 47, in inner
    response = get_response(request)
  File "/usr/local/lib/python3.8/site-packages/django/core/handlers/base.py", line 204, in _get_response
    response = response.render()
  File "/usr/local/lib/python3.8/site-packages/django/template/response.py", line 105, in render
    self.content = self.rendered_content
  File "/usr/local/lib/python3.8/site-packages/rest_framework/response.py", line 70, in rendered_content
    ret = renderer.render(self.data, accepted_media_type, context)
  File "/usr/local/lib/python3.8/site-packages/rest_framework_swagger/renderers.py", line 55, in render
    return render(
  File "/usr/local/lib/python3.8/site-packages/django/shortcuts.py", line 19, in render
    content = loader.render_to_string(template_name, context, request, using=using)
  File "/usr/local/lib/python3.8/site-packages/django/template/loader.py", line 61, in render_to_string
    template = get_template(template_name, using=using)
  File "/usr/local/lib/python3.8/site-packages/django/template/loader.py", line 15, in get_template
    return engine.get_template(template_name)
  File "/usr/local/lib/python3.8/site-packages/django/template/backends/django.py", line 34, in get_template
    return Template(self.engine.get_template(template_name), self)
  File "/usr/local/lib/python3.8/site-packages/django/template/engine.py", line 143, in get_template
    template, origin = self.find_template(template_name)
  File "/usr/local/lib/python3.8/site-packages/django/template/engine.py", line 125, in find_template
    template = loader.get_template(name, skip=skip)
  File "/usr/local/lib/python3.8/site-packages/django/template/loaders/base.py", line 29, in get_template
    return Template(
  File "/usr/local/lib/python3.8/site-packages/django/template/base.py", line 155, in __init__
    self.nodelist = self.compile_nodelist()
  File "/usr/local/lib/python3.8/site-packages/django/template/base.py", line 193, in compile_nodelist
    return parser.parse()
  File "/usr/local/lib/python3.8/site-packages/django/template/base.py", line 478, in parse
    raise self.error(token, e)
  File "/usr/local/lib/python3.8/site-packages/django/template/base.py", line 476, in parse
    compiled_result = compile_func(self, token)
  File "/usr/local/lib/python3.8/site-packages/django/template/defaulttags.py", line 1091, in load
    lib = find_library(parser, name)
  File "/usr/local/lib/python3.8/site-packages/django/template/defaulttags.py", line 1036, in find_library
    raise TemplateSyntaxError(
django.template.exceptions.TemplateSyntaxError: 'staticfiles' is not a registered tag library. Must be one of:
admin_list
admin_modify
admin_urls
cache
i18n
l10n
log
rest_framework
static
tz
Not Found: /
Not Found: /
Not Found: /auth/
Not Found: /favicon.ico
Not Found: /auth/
Not Found: /
Internal Server Error: /swagger/
Traceback (most recent call last):
  File "/usr/local/lib/python3.8/site-packages/django/core/handlers/exception.py", line 47, in inner
    response = get_response(request)
  File "/usr/local/lib/python3.8/site-packages/django/core/handlers/base.py", line 167, in _get_response
    callback, callback_args, callback_kwargs = self.resolve_request(request)
  File "/usr/local/lib/python3.8/site-packages/django/core/handlers/base.py", line 290, in resolve_request
    resolver_match = resolver.resolve(request.path_info)
  File "/usr/local/lib/python3.8/site-packages/django/urls/resolvers.py", line 556, in resolve
    for pattern in self.url_patterns:
  File "/usr/local/lib/python3.8/site-packages/django/utils/functional.py", line 48, in __get__
    res = instance.__dict__[self.name] = self.func(instance)
  File "/usr/local/lib/python3.8/site-packages/django/urls/resolvers.py", line 598, in url_patterns
    patterns = getattr(self.urlconf_module, "urlpatterns", self.urlconf_module)
  File "/usr/local/lib/python3.8/site-packages/django/utils/functional.py", line 48, in __get__
    res = instance.__dict__[self.name] = self.func(instance)
  File "/usr/local/lib/python3.8/site-packages/django/urls/resolvers.py", line 591, in urlconf_module
    return import_module(self.urlconf_name)
  File "/usr/local/lib/python3.8/importlib/__init__.py", line 127, in import_module
    return _bootstrap._gcd_import(name[level:], package, level)
  File "<frozen importlib._bootstrap>", line 1014, in _gcd_import
  File "<frozen importlib._bootstrap>", line 991, in _find_and_load
  File "<frozen importlib._bootstrap>", line 975, in _find_and_load_unlocked
  File "<frozen importlib._bootstrap>", line 671, in _load_unlocked
  File "<frozen importlib._bootstrap_external>", line 783, in exec_module
  File "<frozen importlib._bootstrap>", line 219, in _call_with_frames_removed
  File "/usr/src/djangoBlogAPI/urls.py", line 41, in <module>
    path('api/v1/', include('users.urls')),
  File "/usr/local/lib/python3.8/site-packages/django/urls/conf.py", line 34, in include
    urlconf_module = import_module(urlconf_module)
  File "/usr/local/lib/python3.8/importlib/__init__.py", line 127, in import_module
    return _bootstrap._gcd_import(name[level:], package, level)
  File "<frozen importlib._bootstrap>", line 1014, in _gcd_import
  File "<frozen importlib._bootstrap>", line 991, in _find_and_load
  File "<frozen importlib._bootstrap>", line 975, in _find_and_load_unlocked
  File "<frozen importlib._bootstrap>", line 671, in _load_unlocked
  File "<frozen importlib._bootstrap_external>", line 783, in exec_module
  File "<frozen importlib._bootstrap>", line 219, in _call_with_frames_removed
  File "/usr/src/users/urls.py", line 3, in <module>
    from src.users.views import UserRegistration, ChangePasswordUser
ModuleNotFoundError: No module named 'src'
Internal Server Error: /api/v1/create_user/
Traceback (most recent call last):
  File "/usr/local/lib/python3.8/site-packages/rest_framework/fields.py", line 457, in get_attribute
    return get_attribute(instance, self.source_attrs)
  File "/usr/local/lib/python3.8/site-packages/rest_framework/fields.py", line 97, in get_attribute
    instance = getattr(instance, attr)
AttributeError: 'User' object has no attribute 'password2'

During handling of the above exception, another exception occurred:

Traceback (most recent call last):
  File "/usr/local/lib/python3.8/site-packages/django/core/handlers/exception.py", line 47, in inner
    response = get_response(request)
  File "/usr/local/lib/python3.8/site-packages/django/core/handlers/base.py", line 181, in _get_response
    response = wrapped_callback(request, *callback_args, **callback_kwargs)
  File "/usr/local/lib/python3.8/site-packages/django/views/decorators/csrf.py", line 54, in wrapped_view
    return view_func(*args, **kwargs)
  File "/usr/local/lib/python3.8/site-packages/rest_framework/viewsets.py", line 125, in view
    return self.dispatch(request, *args, **kwargs)
  File "/usr/local/lib/python3.8/site-packages/rest_framework/views.py", line 509, in dispatch
    response = self.handle_exception(exc)
  File "/usr/local/lib/python3.8/site-packages/rest_framework/views.py", line 469, in handle_exception
    self.raise_uncaught_exception(exc)
  File "/usr/local/lib/python3.8/site-packages/rest_framework/views.py", line 480, in raise_uncaught_exception
    raise exc
  File "/usr/local/lib/python3.8/site-packages/rest_framework/views.py", line 506, in dispatch
    response = handler(request, *args, **kwargs)
  File "/usr/src/users/views.py", line 26, in create
    return Response(show_serializer.data, status=status.HTTP_201_CREATED)
  File "/usr/local/lib/python3.8/site-packages/rest_framework/serializers.py", line 548, in data
    ret = super().data
  File "/usr/local/lib/python3.8/site-packages/rest_framework/serializers.py", line 246, in data
    self._data = self.to_representation(self.instance)
  File "/usr/local/lib/python3.8/site-packages/rest_framework/serializers.py", line 502, in to_representation
    attribute = field.get_attribute(instance)
  File "/usr/local/lib/python3.8/site-packages/rest_framework/fields.py", line 490, in get_attribute
    raise type(exc)(msg)
AttributeError: Got AttributeError when attempting to get a value for field `password2` on serializer `UserRegistrationSerializer`.
The serializer field might be named incorrectly and not match any attribute or key on the `User` instance.
Original exception text was: 'User' object has no attribute 'password2'.
Bad Request: /api/v1/create_user/
Bad Request: /api/v1/create_user/
Bad Request: /api/v1/create_user/
Bad Request: /api/v1/create_user/
Unauthorized: /auth/jwt/create/
Not Found: /favicon.ico
Internal Server Error: /api/v1/create_user/
Traceback (most recent call last):
  File "/usr/local/lib/python3.8/site-packages/django/core/handlers/exception.py", line 47, in inner
    response = get_response(request)
  File "/usr/local/lib/python3.8/site-packages/django/core/handlers/base.py", line 181, in _get_response
    response = wrapped_callback(request, *callback_args, **callback_kwargs)
  File "/usr/local/lib/python3.8/site-packages/django/views/decorators/csrf.py", line 54, in wrapped_view
    return view_func(*args, **kwargs)
  File "/usr/local/lib/python3.8/site-packages/rest_framework/viewsets.py", line 125, in view
    return self.dispatch(request, *args, **kwargs)
  File "/usr/local/lib/python3.8/site-packages/rest_framework/views.py", line 509, in dispatch
    response = self.handle_exception(exc)
  File "/usr/local/lib/python3.8/site-packages/rest_framework/views.py", line 469, in handle_exception
    self.raise_uncaught_exception(exc)
  File "/usr/local/lib/python3.8/site-packages/rest_framework/views.py", line 480, in raise_uncaught_exception
    raise exc
  File "/usr/local/lib/python3.8/site-packages/rest_framework/views.py", line 506, in dispatch
    response = handler(request, *args, **kwargs)
  File "/usr/src/users/views.py", line 26, in create
    return Response(show_serializer.data, status=status.HTTP_201_CREATED)
TypeError: __init__() got an unexpected keyword argument 'status'
Bad Request: /api/v1/create_user/
Not Found: /favicon.ico
Internal Server Error: /api/v1/change_password/
Traceback (most recent call last):
  File "/usr/local/lib/python3.8/site-packages/django/core/handlers/exception.py", line 47, in inner
    response = get_response(request)
  File "/usr/local/lib/python3.8/site-packages/django/core/handlers/base.py", line 181, in _get_response
    response = wrapped_callback(request, *callback_args, **callback_kwargs)
  File "/usr/local/lib/python3.8/site-packages/django/views/decorators/csrf.py", line 54, in wrapped_view
    return view_func(*args, **kwargs)
  File "/usr/local/lib/python3.8/site-packages/rest_framework/viewsets.py", line 125, in view
    return self.dispatch(request, *args, **kwargs)
  File "/usr/local/lib/python3.8/site-packages/rest_framework/views.py", line 509, in dispatch
    response = self.handle_exception(exc)
  File "/usr/local/lib/python3.8/site-packages/rest_framework/views.py", line 469, in handle_exception
    self.raise_uncaught_exception(exc)
  File "/usr/local/lib/python3.8/site-packages/rest_framework/views.py", line 480, in raise_uncaught_exception
    raise exc
  File "/usr/local/lib/python3.8/site-packages/rest_framework/views.py", line 506, in dispatch
    response = handler(request, *args, **kwargs)
  File "/usr/src/users/views.py", line 46, in update
    serializer.is_valid(raise_exception=True)
  File "/usr/local/lib/python3.8/site-packages/rest_framework/serializers.py", line 220, in is_valid
    self._validated_data = self.run_validation(self.initial_data)
  File "/usr/local/lib/python3.8/site-packages/rest_framework/serializers.py", line 423, in run_validation
    assert value is not None, '.validate() should return the validated data'
AssertionError: .validate() should return the validated data
Forbidden: /api/v1/change_password/
Forbidden: /api/v1/create_user/
Forbidden: /api/v1/create_user/
Forbidden: /api/v1/change_password/
Forbidden: /api/v1/create_user/
Forbidden: /api/v1/create_user/
Forbidden: /api/v1/change_password/
Forbidden: /api/v1/create_user/
Forbidden: /api/v1/create_user/
Forbidden: /api/v1/change_password/
Forbidden: /api/v1/create_user/
Forbidden: /api/v1/create_user/
Forbidden: /api/v1/change_password/
Forbidden: /api/v1/create_user/
Forbidden: /api/v1/create_user/
Forbidden: /api/v1/change_password/
Forbidden: /api/v1/create_user/
Forbidden: /api/v1/create_user/
Bad Request: /api/v1/change_password/
Method Not Allowed: /api/v1/create_user/
Bad Request: /api/v1/change_password/
Method Not Allowed: /api/v1/create_user/
Bad Request: /api/v1/change_password/
Method Not Allowed: /api/v1/create_user/
Bad Request: /api/v1/change_password/
Method Not Allowed: /api/v1/create_user/
Bad Request: /api/v1/change_password/
Method Not Allowed: /api/v1/create_user/
Bad Request: /api/v1/change_password/
Method Not Allowed: /api/v1/create_user/
Internal Server Error: /api/v1/change_password/
Traceback (most recent call last):
  File "/usr/local/lib/python3.8/site-packages/django/core/handlers/exception.py", line 47, in inner
    response = get_response(request)
  File "/usr/local/lib/python3.8/site-packages/django/core/handlers/base.py", line 181, in _get_response
    response = wrapped_callback(request, *callback_args, **callback_kwargs)
  File "/usr/local/lib/python3.8/site-packages/django/views/decorators/csrf.py", line 54, in wrapped_view
    return view_func(*args, **kwargs)
  File "/usr/local/lib/python3.8/site-packages/rest_framework/viewsets.py", line 125, in view
    return self.dispatch(request, *args, **kwargs)
  File "/usr/local/lib/python3.8/site-packages/rest_framework/views.py", line 509, in dispatch
    response = self.handle_exception(exc)
  File "/usr/local/lib/python3.8/site-packages/rest_framework/views.py", line 469, in handle_exception
    self.raise_uncaught_exception(exc)
  File "/usr/local/lib/python3.8/site-packages/rest_framework/views.py", line 480, in raise_uncaught_exception
    raise exc
  File "/usr/local/lib/python3.8/site-packages/rest_framework/views.py", line 506, in dispatch
    response = handler(request, *args, **kwargs)
  File "/usr/src/users/views.py", line 46, in update
    serializer.is_valid(raise_exception=True)
  File "/usr/local/lib/python3.8/site-packages/rest_framework/serializers.py", line 220, in is_valid
    self._validated_data = self.run_validation(self.initial_data)
  File "/usr/local/lib/python3.8/site-packages/rest_framework/serializers.py", line 423, in run_validation
    assert value is not None, '.validate() should return the validated data'
AssertionError: .validate() should return the validated data
Method Not Allowed: /api/v1/create_user/
Method Not Allowed: /api/v1/create_user/
